Traceback (most recent call last):
  File "/opt/hostedtoolcache/Python/3.10.18/x64/lib/python3.10/site-packages/jupyter_cache/executors/utils.py", line 58, in single_nb_execution
    executenb(
  File "/opt/hostedtoolcache/Python/3.10.18/x64/lib/python3.10/site-packages/nbclient/client.py", line 1319, in execute
    return NotebookClient(nb=nb, resources=resources, km=km, **kwargs).execute()
  File "/opt/hostedtoolcache/Python/3.10.18/x64/lib/python3.10/site-packages/jupyter_core/utils/__init__.py", line 165, in wrapped
    return loop.run_until_complete(inner)
  File "/opt/hostedtoolcache/Python/3.10.18/x64/lib/python3.10/asyncio/base_events.py", line 649, in run_until_complete
    return future.result()
  File "/opt/hostedtoolcache/Python/3.10.18/x64/lib/python3.10/site-packages/nbclient/client.py", line 709, in async_execute
    await self.async_execute_cell(
  File "/opt/hostedtoolcache/Python/3.10.18/x64/lib/python3.10/site-packages/nbclient/client.py", line 1062, in async_execute_cell
    await self._check_raise_for_error(cell, cell_index, exec_reply)
  File "/opt/hostedtoolcache/Python/3.10.18/x64/lib/python3.10/site-packages/nbclient/client.py", line 918, in _check_raise_for_error
    raise CellExecutionError.from_cell_and_msg(cell, exec_reply_content)
nbclient.exceptions.CellExecutionError: An error occurred while executing the following cell:
------------------
result_df = test_vehicle.predict(df, ['grade_dec', 'speed_mph','road_class'], 'miles', True)
result_df.head()
------------------


[0;31m---------------------------------------------------------------------------[0m
[0;31mTypeError[0m                                 Traceback (most recent call last)
Cell [0;32mIn[12], line 1[0m
[0;32m----> 1[0m result_df [38;5;241m=[39m [43mtest_vehicle[49m[38;5;241;43m.[39;49m[43mpredict[49m[43m([49m[43mdf[49m[43m,[49m[43m [49m[43m[[49m[38;5;124;43m'[39;49m[38;5;124;43mgrade_dec[39;49m[38;5;124;43m'[39;49m[43m,[49m[43m [49m[38;5;124;43m'[39;49m[38;5;124;43mspeed_mph[39;49m[38;5;124;43m'[39;49m[43m,[49m[38;5;124;43m'[39;49m[38;5;124;43mroad_class[39;49m[38;5;124;43m'[39;49m[43m][49m[43m,[49m[43m [49m[38;5;124;43m'[39;49m[38;5;124;43mmiles[39;49m[38;5;124;43m'[39;49m[43m,[49m[43m [49m[38;5;28;43;01mTrue[39;49;00m[43m)[49m
[1;32m      2[0m result_df[38;5;241m.[39mhead()

[0;31mTypeError[0m: Model.predict() takes from 2 to 4 positional arguments but 5 were given

