Traceback (most recent call last):
  File "/opt/hostedtoolcache/Python/3.10.14/x64/lib/python3.10/site-packages/jupyter_cache/executors/utils.py", line 58, in single_nb_execution
    executenb(
  File "/opt/hostedtoolcache/Python/3.10.14/x64/lib/python3.10/site-packages/nbclient/client.py", line 1314, in execute
    return NotebookClient(nb=nb, resources=resources, km=km, **kwargs).execute()
  File "/opt/hostedtoolcache/Python/3.10.14/x64/lib/python3.10/site-packages/jupyter_core/utils/__init__.py", line 165, in wrapped
    return loop.run_until_complete(inner)
  File "/opt/hostedtoolcache/Python/3.10.14/x64/lib/python3.10/asyncio/base_events.py", line 649, in run_until_complete
    return future.result()
  File "/opt/hostedtoolcache/Python/3.10.14/x64/lib/python3.10/site-packages/nbclient/client.py", line 709, in async_execute
    await self.async_execute_cell(
  File "/opt/hostedtoolcache/Python/3.10.14/x64/lib/python3.10/site-packages/nbclient/client.py", line 1062, in async_execute_cell
    await self._check_raise_for_error(cell, cell_index, exec_reply)
  File "/opt/hostedtoolcache/Python/3.10.14/x64/lib/python3.10/site-packages/nbclient/client.py", line 918, in _check_raise_for_error
    raise CellExecutionError.from_cell_and_msg(cell, exec_reply_content)
nbclient.exceptions.CellExecutionError: An error occurred while executing the following cell:
------------------
camry.predict(sample_route)
------------------


[0;31m---------------------------------------------------------------------------[0m
[0;31mValueError[0m                                Traceback (most recent call last)
Cell [0;32mIn[6], line 1[0m
[0;32m----> 1[0m [43mcamry[49m[38;5;241;43m.[39;49m[43mpredict[49m[43m([49m[43msample_route[49m[43m)[49m

File [0;32m/opt/hostedtoolcache/Python/3.10.14/x64/lib/python3.10/site-packages/nrel/routee/powertrain/core/model.py:309[0m, in [0;36mModel.predict[0;34m(self, links_df, feature_columns, distance_column, apply_real_world_adjustment)[0m
[1;32m    307[0m     distance_column [38;5;241m=[39m config[38;5;241m.[39mdistance[38;5;241m.[39mname
[1;32m    308[0m     [38;5;28;01mif[39;00m distance_column [38;5;129;01mnot[39;00m [38;5;129;01min[39;00m links_df[38;5;241m.[39mcolumns:
[0;32m--> 309[0m         [38;5;28;01mraise[39;00m [38;5;167;01mValueError[39;00m(
[1;32m    310[0m             [38;5;124mf[39m[38;5;124m"[39m[38;5;124mlinks_df must contain a distance column named: [39m[38;5;124m'[39m[38;5;132;01m{[39;00mdistance_column[38;5;132;01m}[39;00m[38;5;124m'[39m[38;5;124m"[39m
[1;32m    311[0m         )
[1;32m    312[0m [38;5;28;01melse[39;00m:
[1;32m    313[0m     links_df [38;5;241m=[39m links_df[38;5;241m.[39mrename(columns[38;5;241m=[39m{distance_column: config[38;5;241m.[39mdistance[38;5;241m.[39mname})

[0;31mValueError[0m: links_df must contain a distance column named: 'distance'

