Traceback (most recent call last):
  File "/opt/hostedtoolcache/Python/3.10.18/x64/lib/python3.10/site-packages/jupyter_core/utils/__init__.py", line 154, in wrapped
    asyncio.get_running_loop()
RuntimeError: no running event loop

During handling of the above exception, another exception occurred:

Traceback (most recent call last):
  File "/opt/hostedtoolcache/Python/3.10.18/x64/lib/python3.10/site-packages/jupyter_cache/executors/utils.py", line 58, in single_nb_execution
    executenb(
  File "/opt/hostedtoolcache/Python/3.10.18/x64/lib/python3.10/site-packages/nbclient/client.py", line 1319, in execute
    return NotebookClient(nb=nb, resources=resources, km=km, **kwargs).execute()
  File "/opt/hostedtoolcache/Python/3.10.18/x64/lib/python3.10/site-packages/jupyter_core/utils/__init__.py", line 158, in wrapped
    return loop.run_until_complete(inner)
  File "/opt/hostedtoolcache/Python/3.10.18/x64/lib/python3.10/asyncio/base_events.py", line 649, in run_until_complete
    return future.result()
  File "/opt/hostedtoolcache/Python/3.10.18/x64/lib/python3.10/site-packages/nbclient/client.py", line 709, in async_execute
    await self.async_execute_cell(
  File "/opt/hostedtoolcache/Python/3.10.18/x64/lib/python3.10/site-packages/nbclient/client.py", line 1062, in async_execute_cell
    await self._check_raise_for_error(cell, cell_index, exec_reply)
  File "/opt/hostedtoolcache/Python/3.10.18/x64/lib/python3.10/site-packages/nbclient/client.py", line 918, in _check_raise_for_error
    raise CellExecutionError.from_cell_and_msg(cell, exec_reply_content)
nbclient.exceptions.CellExecutionError: An error occurred while executing the following cell:
------------------
sample_route["grade_percent"] = sample_route.grade_dec * 100
sample_route = sample_route.drop(columns="grade_dec")
sample_route = sample_route.rename(columns={"miles": "distance"})
sample_route
------------------


[0;31m---------------------------------------------------------------------------[0m
[0;31mAttributeError[0m                            Traceback (most recent call last)
[0;32m/tmp/ipykernel_2256/497135928.py[0m in [0;36m?[0;34m()[0m
[0;32m----> 1[0;31m [0msample_route[0m[0;34m[[0m[0;34m"grade_percent"[0m[0;34m][0m [0;34m=[0m [0msample_route[0m[0;34m.[0m[0mgrade_dec[0m [0;34m*[0m [0;36m100[0m[0;34m[0m[0;34m[0m[0m
[0m[1;32m      2[0m [0msample_route[0m [0;34m=[0m [0msample_route[0m[0;34m.[0m[0mdrop[0m[0;34m([0m[0mcolumns[0m[0;34m=[0m[0;34m"grade_dec"[0m[0;34m)[0m[0;34m[0m[0;34m[0m[0m
[1;32m      3[0m [0msample_route[0m [0;34m=[0m [0msample_route[0m[0;34m.[0m[0mrename[0m[0;34m([0m[0mcolumns[0m[0;34m=[0m[0;34m{[0m[0;34m"miles"[0m[0;34m:[0m [0;34m"distance"[0m[0;34m}[0m[0;34m)[0m[0;34m[0m[0;34m[0m[0m
[1;32m      4[0m [0msample_route[0m[0;34m[0m[0;34m[0m[0m

[0;32m/opt/hostedtoolcache/Python/3.10.18/x64/lib/python3.10/site-packages/pandas/core/generic.py[0m in [0;36m?[0;34m(self, name)[0m
[1;32m   6314[0m             [0;32mand[0m [0mname[0m [0;32mnot[0m [0;32min[0m [0mself[0m[0;34m.[0m[0m_accessors[0m[0;34m[0m[0;34m[0m[0m
[1;32m   6315[0m             [0;32mand[0m [0mself[0m[0;34m.[0m[0m_info_axis[0m[0;34m.[0m[0m_can_hold_identifiers_and_holds_name[0m[0;34m([0m[0mname[0m[0;34m)[0m[0;34m[0m[0;34m[0m[0m
[1;32m   6316[0m         ):
[1;32m   6317[0m             [0;32mreturn[0m [0mself[0m[0;34m[[0m[0mname[0m[0;34m][0m[0;34m[0m[0;34m[0m[0m
[0;32m-> 6318[0;31m         [0;32mreturn[0m [0mobject[0m[0;34m.[0m[0m__getattribute__[0m[0;34m([0m[0mself[0m[0;34m,[0m [0mname[0m[0;34m)[0m[0;34m[0m[0;34m[0m[0m
[0m
[0;31mAttributeError[0m: 'DataFrame' object has no attribute 'grade_dec'

