Traceback (most recent call last):
  File "/opt/hostedtoolcache/Python/3.10.18/x64/lib/python3.10/site-packages/jupyter_core/utils/__init__.py", line 154, in wrapped
    asyncio.get_running_loop()
RuntimeError: no running event loop

During handling of the above exception, another exception occurred:

Traceback (most recent call last):
  File "/opt/hostedtoolcache/Python/3.10.18/x64/lib/python3.10/site-packages/jupyter_cache/executors/utils.py", line 58, in single_nb_execution
    executenb(
  File "/opt/hostedtoolcache/Python/3.10.18/x64/lib/python3.10/site-packages/nbclient/client.py", line 1319, in execute
    return NotebookClient(nb=nb, resources=resources, km=km, **kwargs).execute()
  File "/opt/hostedtoolcache/Python/3.10.18/x64/lib/python3.10/site-packages/jupyter_core/utils/__init__.py", line 158, in wrapped
    return loop.run_until_complete(inner)
  File "/opt/hostedtoolcache/Python/3.10.18/x64/lib/python3.10/asyncio/base_events.py", line 649, in run_until_complete
    return future.result()
  File "/opt/hostedtoolcache/Python/3.10.18/x64/lib/python3.10/site-packages/nbclient/client.py", line 709, in async_execute
    await self.async_execute_cell(
  File "/opt/hostedtoolcache/Python/3.10.18/x64/lib/python3.10/site-packages/nbclient/client.py", line 1062, in async_execute_cell
    await self._check_raise_for_error(cell, cell_index, exec_reply)
  File "/opt/hostedtoolcache/Python/3.10.18/x64/lib/python3.10/site-packages/nbclient/client.py", line 918, in _check_raise_for_error
    raise CellExecutionError.from_cell_and_msg(cell, exec_reply_content)
nbclient.exceptions.CellExecutionError: An error occurred while executing the following cell:
------------------
tesla = pt.load_model("2022_Tesla_Model_3_RWD")
tesla_with_temp_steady = pt.load_model(
    "../../../../Downloads/routee-temperature-models/2022_Tesla_Model_3_RWD_0F_110F_steady.json"
)
tesla_with_temp_transient = pt.load_model(
    "../../../../Downloads/routee-temperature-models/2022_Tesla_Model_3_RWD_0F_110F_transient.json"
)

------------------


[0;31m---------------------------------------------------------------------------[0m
[0;31mValueError[0m                                Traceback (most recent call last)
Cell [0;32mIn[2], line 2[0m
[1;32m      1[0m tesla [38;5;241m=[39m pt[38;5;241m.[39mload_model([38;5;124m"[39m[38;5;124m2022_Tesla_Model_3_RWD[39m[38;5;124m"[39m)
[0;32m----> 2[0m tesla_with_temp_steady [38;5;241m=[39m [43mpt[49m[38;5;241;43m.[39;49m[43mload_model[49m[43m([49m
[1;32m      3[0m [43m    [49m[38;5;124;43m"[39;49m[38;5;124;43m../../../../Downloads/routee-temperature-models/2022_Tesla_Model_3_RWD_0F_110F_steady.json[39;49m[38;5;124;43m"[39;49m
[1;32m      4[0m [43m)[49m
[1;32m      5[0m tesla_with_temp_transient [38;5;241m=[39m pt[38;5;241m.[39mload_model(
[1;32m      6[0m     [38;5;124m"[39m[38;5;124m../../../../Downloads/routee-temperature-models/2022_Tesla_Model_3_RWD_0F_110F_transient.json[39m[38;5;124m"[39m
[1;32m      7[0m )

File [0;32m/opt/hostedtoolcache/Python/3.10.18/x64/lib/python3.10/site-packages/nrel/routee/powertrain/io/load.py:83[0m, in [0;36mload_model[0;34m(name)[0m
[1;32m     81[0m     [38;5;28;01mreturn[39;00m model
[1;32m     82[0m [38;5;28;01melse[39;00m:
[0;32m---> 83[0m     [38;5;28;01mraise[39;00m [38;5;167;01mValueError[39;00m(
[1;32m     84[0m         [38;5;124mf[39m[38;5;124m"[39m[38;5;124mCould not load model: [39m[38;5;132;01m{[39;00mname[38;5;132;01m}[39;00m[38;5;124m.[39m[38;5;124m"[39m
[1;32m     85[0m         [38;5;124m"[39m[38;5;124m try listing available models with pt.list_available_models()[39m[38;5;124m"[39m
[1;32m     86[0m         [38;5;124m"[39m[38;5;124m or providing a path to a local model file.[39m[38;5;124m"[39m
[1;32m     87[0m     )

[0;31mValueError[0m: Could not load model: ../../../../Downloads/routee-temperature-models/2022_Tesla_Model_3_RWD_0F_110F_steady.json. try listing available models with pt.list_available_models() or providing a path to a local model file.

